Workbook
Name B3A12: Dashboard!$B$3
Name R3A1: 'Year Grid'!$R$3
Name C7Z1: Dashboard!$C$7
Name D7P1B3: Dashboard!$D$7

Sheet Dashboard
A1: 📅 TEACHER DASHBOARD — Master Agenda
A3: Today | B3: =TEXT(TODAY(),"dddd, MMMM DD, YYYY") -> Friday, August 07, 2026 | J3: =MIN(MAX(5,5+FLOOR((TODAY()-DATE(2026,8,31))/7,1)),40) -> 5
A5: 🔵 THIS WEEK — Daily Plan at a Glance
B6: 📄 Agenda | C6: Mon | D6: Tue | E6: Wed | F6: Thu | G6: Fri | H6: 🎞 VT
A7: 🌿 Biology | B7: {=IFERROR(HYPERLINK(IFERROR(LOOKUP(TODAY(),'Bio as List'!$I$4:$I$39,'Bio as List'!$J$4:$J$39),INDEX('Bio as List'!$J$4:$J$39,1)),"📄 Agenda ↗"),"📄 —")} -> 📄 Agenda ↗ | C7: {=INDEX('Year Grid'!F:F,$J$3)} -> 8/31 Syllabus · pretest · sign safety sheet · learn to submit Notes (short) | E7: {=INDEX('Year Grid'!G:G,$J$3)} -> 9/2 Lab Safety lecture · Lab Equipment activity · safety cartoon · learn to submit Drafts (long) Notes.Introduction to Biology due 9/2 | G7: {=INDEX('Year Grid'!H:H,$J$3)} -> 9/4 OFF — Schools Closed 9/4 (intro week: Notes only) | H7: {=IFERROR(HYPERLINK(IFERROR(LOOKUP(TODAY(),'Bio as List'!$I$4:$I$39,'Bio as List'!$K$4:$K$39),INDEX('Bio as List'!$K$4:$K$39,1)),"🎞 VT ↗"),"🎞 —")} -> 🎞 VT ↗
A8: 🫀 Anatomy & Physiology | B8: {=IFERROR(HYPERLINK(IFERROR(LOOKUP(TODAY(),'A&P as List'!$H$4:$H$38,'A&P as List'!$I$4:$I$38),INDEX('A&P as List'!$I$4:$I$38,1)),"📄 Agenda ↗"),"📄 —")} -> 📄 Agenda ↗ | D8: {=INDEX('Year Grid'!J:J,$J$3)} -> 9/1 Tue: Who Knew? (icebreaker) · Syllabus & topics | F8: {=INDEX('Year Grid'!K:K,$J$3)} -> 9/3 Thu: Body Parts Chalk Outline · Academic Integrity + Bioethics Intro Case (discussion) · Hippocratic Oath (moved from Fri 9/4 — closed) | G8: {=INDEX('Year Grid'!L:L,$J$3)} -> 9/4 OFF — Schools Closed | H8: {=IFERROR(HYPERLINK(IFERROR(LOOKUP(TODAY(),'A&P as List'!$H$4:$H$38,'A&P as List'!$J$4:$J$38),INDEX('A&P as List'!$J$4:$J$38,1)),"🎞 VT ↗"),"🎞 —")} -> 🎞 VT ↗
A9: 🔬 Forensics | B9: {=IFERROR(HYPERLINK(IFERROR(LOOKUP(TODAY(),'Forensics as List'!$H$4:$H$38,'Forensics as List'!$I$4:$I$38),INDEX('Forensics as List'!$I$4:$I$38,1)),"📄 Agenda ↗"),"📄 —")} -> 📄 Agenda ↗ | C9: {=INDEX('Year Grid'!N:N,$J$3)} -> 8/31 First day — rules & procedures | E9: {=INDEX('Year Grid'!O:O,$J$3)} -> 9/2 Syllabus + intro to forensic science | G9: {=INDEX('Year Grid'!P:P,$J$3)} -> 9/4 Course overview / intro activity | H9: {=IFERROR(HYPERLINK(IFERROR(LOOKUP(TODAY(),'Forensics as List'!$H$4:$H$38,'Forensics as List'!$J$4:$J$38),INDEX('Forensics as List'!$J$4:$J$38,1)),"🎞 VT ↗"),"🎞 —")} -> 🎞 VT ↗
C10: {=INDEX('Year Task Grid'!C:C,$J$3)} -> WilmU attendance + grading | D10: {=INDEX('Year Task Grid'!D:D,$J$3)} -> Deep work (your choice) | E10: {=INDEX('Year Task Grid'!E:E,$J$3)} -> Deep work (your choice) | F10: {=INDEX('Year Task Grid'!F:F,$J$3)} -> Review Wk 02: Ecosystems & Change / Introduction to Anatomy / Forensics: Lab Safety, Equipment & the Microscope → see Review Links tab | G10: {=INDEX('Year Task Grid'!G:G,$J$3)} -> OFF — Schools Closed 9/4

Sheet Year Grid
A1: Master Agenda — Year Grid 2026–2027 | Biology • Anatomy & Physiology • Forensics | Dr. von Duyke
A2: SCHEDULE | E2: 🌿 BIOLOGY — tagged by concept cycle (link → cycle folder) | I2: 🫀 ANATOMY & PHYSIOLOGY | M2: 🔬 FORENSICS
A3: Wk | B3: MP | C3: Dates / Off-days | D3: Quick Notes | E3: Bio Topic ↗ + VT + Fiddle (A-Day only) | F3: ☀ Mon | G3: ☀ Wed | H3: ☀ Fri | I3: A&P Topic ↗ + VT + Fiddle | J3: Tue | K3: Thu | L3: ☀ Fri | M3: Forensics Topic ↗ + VT + Fiddle (both sections = A-Day) | N3: ☀ Mon | O3: ☀ Wed | P3: Fri (EOW)
A4: ──── MP 1 ────────────────────────────────────────────────────────────
A5: Wk 01 | B5: MP 1 | C5: Aug 31 – Sep 04, 2026 ⚠ Fri 09/04 Schools Closed | D5: ✔️add cartoon to schoology, just notes turned in this week | E5: =HYPERLINK("https://drive.google.com/drive/folders/1Dl_UEI3IaVyiebXUyEZmHNpWExA5H9uT","◆ Cycle 01 · Course Launch & Lab Safety Introduction to Biology (Syllabus · Lab Safety · Lab Equipment · Characteristics of Life · Microscope) VT Folder") -> ◆ Cycle 01 · Course Launch & Lab Safety Introduction to Biology (Syllabus · Lab Safety · Lab Equipment · Characteristics of Life · Microscope) VT Folder | F5: 8/31 Syllabus · pretest · sign safety sheet · learn to submit Notes (short) | G5: 9/2 Lab Safety lecture · Lab Equipment activity · safety cartoon · learn to submit Drafts (long) Notes.Introduction to Biology due 9/2 | H5: 9/4 OFF — Schools Closed 9/4 (intro week: Notes only) | I5: Course Overview & First Day Activities ↗ — Activities — • Fiddle (slides): "Body Basics" myth-buster poll (Kahoot) • Short: Who Knew? icebreaker · Body Parts Chalk Outline (group) • Long: Academic Integrity / Bioethics intro case + Hippocratic Oath discussion • Alts: Visible Body free tour clip / "what does a physiologist do?" think-pair-share / syllabus scavenger hunt | J5: 9/1 Tue: Who Knew? (icebreaker) · Syllabus & topics | K5: 9/3 Thu: Body Parts Chalk Outline · Academic Integrity + Bioethics Intro Case (discussion) · Hippocratic Oath (moved from Fri 9/4 — closed) | L5: 9/4 OFF — Schools Closed | M5: First Day of School & Classroom Rules and Procedures VT Folder | N5: 8/31 First day — rules & procedures | O5: 9/2 Syllabus + intro to forensic science | P5: 9/4 Course overview / intro activity
A6: Wk 02 | B6: MP 1 | C6: Sep 07 – Sep 11, 2026 ⚠ Mon 09/07 Labor Day | E6: =HYPERLINK("https://drive.google.com/drive/folders/1D3n02wUGdTlje3GsH52JYRRbNN_KRCYv","◆ Cycle 02 · Ecosystems & Feeding Ecosystems & Change (Introduction to Ecology VT) VT Folder") -> ◆ Cycle 02 · Ecosystems & Feeding Ecosystems & Change (Introduction to Ecology VT) VT Folder | F6: 9/7 OFF — Labor Day 9/7 | G6: 9/9 Intro to Ecology lesson + Habitats game · Feeding relationships food-web (NW) write-up (short→long) Notes.Ecosystems & Change due 9/9 | H6: 9/11 Finish labs/activities · catch-up (no Draft — Wk01 Intro to Biology was Notes only) | I6: Introduction to Anatomy ↗ — Activities — (CA: homeostasis via feedback) • Fiddle (slides): LabXchange body-systems explorer / pulse-after-jumping-jacks demo • Short: Kati Mori marathon case — predict the feedback response • Long: Feedback Loops modeling — negative vs positive (core CA) • Alts: HHMI homeostasis clip / Why Do We Need Air Pressure? reasoning / Body Regions–Cavities labels (open-book ref) | J6: 9/8 Tue: Lesson: Introduction to Anatomy · Case: Kati Mori (marathon) | K6: 9/10 Thu: Feedback Loops (homeostasis — core) | L6: 9/11 Fri: Why Do We Need Air Pressure? · Open-book ref (don't memorize): Body Regions / Body Cavities labels, Body Systems organizer | M6: Lab Safety, Lab Equipment & The Microscope Folder | N6: 9/7 ⚠ Labor Day — no school | O6: 9/9 Lab safety + equipment ID | P6: 9/11 The microscope — intro & use
A7: Wk 03 | B7: MP 1 | C7: Sep 14 – Sep 18, 2026 ⚠ Tue 09/15 Teacher In-Service | E7: ◆ Cycle 02 · Ecosystems & Feeding Intro to Energy (VT Inserts — autotrophs/heterotrophs + energy loss) VT Folder | F7: 9/14 Intro to Energy lesson · Autotroph vs heterotroph card sort (short) 📝 DRAFT.Ecosystems & Change due 9/14 | G7: 9/16 Energy-loss pyramid / 10% rule stations + write-up (long) Notes.Intro to Energy due 9/16 | H7: 9/18 Finish labs/activities | I7: Introduction to Anatomy (cont.) ↗ — Activities — • Fiddle (slides): directional-terms quick drill (Kenhub free) • Short: A Promising Therapy for Diabetes — case read • Long: Gummy Bear Dissection (osmosis → homeostasis link) • Alts: anatomical-position charades / planes & sections image sort / Review Guide (open-book) before Unit Exam | J7: 9/15 OFF — In-Service | K7: 9/17 Thu: Case: A Promising Therapy for Diabetes + Lab: Gummy Bear Dissection (moved from Tue 9/15 — in-service) | L7: 9/18 Fri: Review Guide (open-book) · 📝 UNIT EXAM — Introduction to Anatomy | M7: Observation Skills & Deductive Reasoning VT Folder | N7: 9/14 Intro to Forensics + Eyewitness — lesson + short: eyewitness account analysis | O7: 9/16 CSI overview activity · 📝 Notes due | P7: 9/18 Catch-up / flex (EOW)
A8: Wk 04 | B8: MP 1 | C8: Sep 21 – Sep 25, 2026 ⚠ Mon 09/21 Schools Closed | E8: =HYPERLINK("https://drive.google.com/drive/folders/1CZGfr19RTWJlHZBvydbMpc3twyDwxAq3","◆ Cycle 03 · Energy Flow Energy Flow (Energy Flow Lesson VT) VT Folder") -> ◆ Cycle 03 · Energy Flow Energy Flow (Energy Flow Lesson VT) VT Folder | F8: 9/21 OFF — Schools Closed 9/21 | G8: 9/23 Energy Flow lesson + arrow draw · Energy Flow Stations + write-up, label vocab (short→long) Notes.Energy Flow due 9/23 📝 DRAFT.Intro to Energy due 9/23 (Mon off) | H8: 9/25 Finish labs/activities | I8: Cell Structure and Function ↗ — Activities — • Fiddle (slides): BioMan Cell Explorer / Learn.Genetics Cell Size & Scale • Short: Mackenzie (PCD) case — cilia structure→function • Long: Viewing Human Cells (microscope lab) • Alts: build-a-cell organelle sort / CER on Mitochondria & Aging / Cell Graphic Organizer (open-book ref) | J8: 9/22 Tue: Lesson: Cell Structure & Function · Case: Mackenzie (PCD) | K8: 9/24 Thu: Lab: Viewing Human Cells | L8: 9/25 Fri: Mitochondria and Aging (CER) · Open-book ref: Cell Graphic Organizer | M8: Eye Witness Testimony & The Innocence Project VT Folder | N8: 9/21 OFF — Schools Closed | O8: 9/23 Investigative Processes (Steps of CSI) + Types of Evidence — lesson (moved from Mon 9/21 — closed) + Evidence-type stations · 📝 Notes due 📝 DRAFT.Intro to Forensics + Eyewitness Accounts due 9/23 (Mon off) | P8: 9/25 Catch-up / flex (EOW)
A9: Wk 05 | B9: MP 1 | C9: Sep 28 – Oct 02, 2026 | E9: =HYPERLINK("https://drive.google.com/drive/folders/1_7LjuC8A4GmfR9bNk_4h8Fcvgc1uONsR","◆ Cycle 04 · Carbon Cycle Biogeochemical Cycles (Biogeochemical Cycles Lesson) VT Folder") -> ◆ Cycle 04 · Carbon Cycle Biogeochemical Cycles (Biogeochemical Cycles Lesson) VT Folder | F9: 9/28 Biogeochemical Cycles lesson · HHMI 'The Tree' carbon intro – Part 1 (short) 📝 DRAFT.Energy Flow due 9/28 | G9: 9/30 Journey through the Carbon Cycle sim – Part 2 + write-up (long) Notes.Biogeochemical Cycles due 9/30 | H9: 10/2 Finish labs/activities | I9: Cell Structure and Function (cont.) ↗ — Activities — • Fiddle (slides): PhET / BioMan osmosis sim • Short: Medical Errors (IV Fluids) — tonicity application • Long: Mitosis, Cancer & Vaccines case stations • Alts: HHMI Cell Cycle & Cancer clip / osmosis egg demo / Cell Cycle–Disorders organizer (open-book) before Unit Exam | J9: 9/29 Tue: Medical Errors (IV Fluids) — osmosis application | K9: 10/1 Thu: Case: Mitosis, Cancer & Vaccines 🦄 | L9: 10/2 Fri: Open-book review · 📝 UNIT EXAM — Cells · ref: Cell Cycle / Cell Disorders organizers | M9: Investigative Processes & Types of Evidence VT Folder | N9: 9/28 Observation & deductive-reasoning practice (not VT) 📝 DRAFT.Investigative Processes (Steps of CSI) + Types of Evidence due 9/28 | O9: 9/30 Observation lab / reasoning puzzles | P9: 10/2 Catch-up / flex (EOW)
A10: Wk 06 | B10: MP 1 | C10: Oct 05 – Oct 09, 2026 | E10: =HYPERLINK("https://drive.google.com/drive/folders/11BNokJq2E4wFOfR2-uTrHxNZ8iO6C3pb","◆ Cycle 05 · Photosynthesis Photosynthesis (Photosynthesis Lesson VT) VT Folder") -> ◆ Cycle 05 · Photosynthesis Photosynthesis (Photosynthesis Lesson VT) VT Folder | F10: 10/5 Photosynthesis lesson · molecular build of the equation – Photosyn 1 (short) 📝 DRAFT.Biogeochemical Cycles due 10/5 | G10: 10/7 Leaf disc lab – Photosyn 2 + write-up (long) Notes.Photosynthesis due 10/7 | H10: 10/9 Finish labs/activities | I10: Body Tissues ↗ — Activities — • Fiddle (slides): tissue-ID slideshow drill (Biology Corner) • Short: Ella (epidermolysis bullosa) — skin structure→function • Long: Viewing Skin Cells (microscope lab) • Alts: 4-tissue-types card sort / What Causes Goosebumps? reasoning / Epidermis Labeling + Tissues Chart (open-book ref) | J10: 10/6 Tue: Lesson: Body Tissues · Case: Ella (epidermolysis bullosa) | K10: 10/8 Thu: Lab: Viewing Skin Cells | L10: 10/9 Fri: What Causes Goosebumps? · Open-book ref (don't memorize): Epidermis Labeling, Tissues Chart | M10: Searching the Scene & Photographing the Crime Scene VT Folder | N10: 10/5 Searching the Scene + Crime Scene Photography — lesson + short | O10: 10/7 Search-patterns activity · 📝 Notes due | P10: 10/9 Catch-up / flex (EOW)
A11: Wk 07 | B11: MP 1 | C11: Oct 12 – Oct 16, 2026 ⚠ Fri 10/16 In-Service — Schools Closed | E11: =HYPERLINK("https://drive.google.com/drive/folders/1BnHejNBE_rJiRkDlK-VrlYY78sTLEhBe","◆ Cycle 06 · Respiration & Fermentation Cellular Respiration (Cellular Respiration VT) VT Folder") -> ◆ Cycle 06 · Respiration & Fermentation Cellular Respiration (Cellular Respiration VT) VT Folder | F11: 10/12 Cellular Respiration lesson · respiration fiddle game + worksheet (short) 📝 DRAFT.Photosynthesis due 10/12 | G11: 10/14 Photosynthesis vs respiration comparison + write-up (long) Notes.Cellular Respiration due 10/14 | H11: 10/16 OFF — In-Service (Schools Closed) | I11: Body Tissues (cont.) ↗ — Activities — • Fiddle (slides): HHMI Biology of Skin Color interactive • Short: Gene Therapy for Butterfly Children (bioethics) • Long: melanin / skin-color data interpretation (HHMI) • Alts: connective-tissue coloring / tissue-reinforcement worksheet / histology microscope rotation before Unit Exam | J11: 10/13 Tue: Gene Therapy for Butterfly Children (bioethics case) + Biology of Skin Color (HHMI interactive) (moved from Thu 10/15) | K11: 10/15 Thu: 📝 UNIT EXAM — Body Tissues (moved from Fri 10/16 — in-service) · Open-book review · ref: Connective Tissue Coloring, Tissue Reinforcement | L11: 10/16 OFF — In-Service (Schools Closed) | M11: Sketching the Scene & Evidence Collection VT Folder | N11: 10/12 Sketching the Scene + Evidence Collection — lesson + short 📝 DRAFT.Searching the Scene + Crime Scene Photography due 10/12 | O11: 10/14 Rough-to-scale sketch (long) · 📝 Notes due | P11: 10/16 OFF — In-Service (Schools Closed)
A12: Wk 08 | B12: MP 1 | C12: Oct 19 – Oct 23, 2026 | E12: =HYPERLINK("https://drive.google.com/drive/folders/1BnHejNBE_rJiRkDlK-VrlYY78sTLEhBe","◆ Cycle 06 · Respiration & Fermentation Fermentation (Fermentation Lesson VT) VT Folder") -> ◆ Cycle 06 · Respiration & Fermentation Fermentation (Fermentation Lesson VT) VT Folder | F12: 10/19 Fermentation lesson · yeast-balloon quick demo (short) 📝 DRAFT.Cellular Respiration due 10/19 | G12: 10/21 Yeast fermentation lab — measure CO₂ + write-up (long) Notes.Fermentation due 10/21 | H12: 10/23 Finish labs/activities | I12: Skeletal System ↗ — Activities — (VT deck CAs: #1 bone is living → #2 axial vs appendicular → #3 structure fits function) • Fiddle (slides): eSkeletons.org bone rotator (UT Austin) • Short: "Is bone alive?" osteoblast/osteoclast/osteocyte sort (#1) • Long: Bone Fractures with Carrots — structure fits function (#3) • Alts: axial vs appendicular card sort (#2) / FOP (Jasmin) build-vs-break case / Long Bone + Bone Matrix coloring (open-book ref) | J12: 10/20 Tue: #1 bone is living · #2 axial vs appendicular — Lesson: Skeletal System (VT) · Case: FOP (Jasmin) | K12: 10/22 Thu: #3 structure fits function — Lab: Bone Fractures with Carrots · ref: Long Bone / Bone Matrix coloring | L12: 10/23 Fri: build vs break balance (master idea) — Bone Dysplasias 🦄 + FOP mechanism | M12: History of Forensics VT Folder | N12: 10/19 History of Forensics + Crime Scene to Courtroom + Innocence Project — lesson 📝 DRAFT.Sketching the Scene + Evidence Collection (chain of custody) due 10/19 | O12: 10/21 Mock trial (Sheppard reveal) + timeline · 📝 Notes due | P12: 10/23 Catch-up / flex (EOW)
A13: Wk 09 | B13: MP 1 | C13: Oct 26 – Oct 30, 2026 | E13: =HYPERLINK("https://drive.google.com/drive/folders/18rj5qQxduYLHo1zZ5VLm_JrCjS4Oj2UO","◆ Cycle 07 · Ecosystem Dynamics Ecological Succession (Ecological Succession VT) VT Folder") -> ◆ Cycle 07 · Ecosystem Dynamics Ecological Succession (Ecological Succession VT) VT Folder | F13: 10/26 Ecological Succession lesson · primary vs secondary card sequence (short) 📝 DRAFT.Fermentation due 10/26 | G13: 10/28 Succession case-study model build + write-up (long) Notes.Ecological Succession due 10/28 | H13: 10/30 Finish labs/activities | I13: Skeletal System (cont.) ↗ — Activities — (CA#4 joints → range of motion → #5 fracture → force → #6 bones reveal identity) • Fiddle (slides): GetBodySmart skeleton/joints interactive • Short: classify-your-own-joints (CA#4) · Skeleton/Skull labeling (open-book ref) • Long: Identifying X-rays — fracture pattern → force (CA#5) • Alts: Mystery of the Bones (CA#6) / Estimate Height from long bones → preps Wk10 practical / Bones of the Hand labeling | J13: 10/27 Tue: #4 joints → range of motion — classify-your-own-joints · Open-book ref: Skeleton & Skull labeling, Bones of Hand | K13: 10/29 Thu: #5 fracture pattern → force — Identifying X-rays | L13: 10/30 Fri: #6 bones reveal identity — Mystery of the Bones 🦄 + Estimate Height (lab) → Wk 10 Lab Practical | M13: Unit Review & Assessment Folder | N13: 10/26 Unit 1 — Review 📝 DRAFT.History of Forensics + Crime Scene to Courtroom + Innocence Project due 10/26 | O13: 10/28 📝 Unit 1 Assessment | P13: 10/30 Catch-up / flex (EOW)
A14: ──── MP 2 ────────────────────────────────────────────────────────────
A15: Wk 10 | B15: MP 2 | C15: Nov 02 – Nov 06, 2026 ⚠ Tue 11/3 Election Day — Schools Closed | E15: =HYPERLINK("https://drive.google.com/drive/folders/18rj5qQxduYLHo1zZ5VLm_JrCjS4Oj2UO","◆ Cycle 07 · Ecosystem Dynamics Population Ecology (Population Ecology VT · HHMI Population Dynamics) VT Folder") -> ◆ Cycle 07 · Ecosystem Dynamics Population Ecology (Population Ecology VT · HHMI Population Dynamics) VT Folder | F15: 11/2 Population Ecology lesson · HHMI Population Dynamics fiddle (short) 📝 DRAFT.Ecological Succession due 11/2 | G15: 11/4 Carrying Capacity & Limiting Factors — Oh Deer! activity (long) Notes.Population Ecology due 11/4 | H15: 11/6 Finish labs/activities | I15: 💀 Skeletal Anatomy (Lab Practical) ↗ — Activities — • Fiddle (slides): station-map warm-up • Short: pre-practical bone-station review circuit • Long: 📝 Skeletal Lab Practical (stations) • Alts: eSkeletons self-quiz / peer flash-card relay / labeled-skeleton speed round | J15: 11/3 OFF — Election Day (Schools Closed) | K15: 11/5 Thu: 📝 Skeletal Lab Practical (EXAM) (moved from Tue 11/3 — Election Day) | M15: Mock Crime Scene Folder | N15: 11/2 Mon: Process the scene — secure & document (sketch, photos), collect & package evidence, chain of custody | O15: 11/4 Wed: Lab analysis of collected evidence · build the case · mock investigative briefing + reveal/debrief | P15: 11/6 Catch-up / flex (EOW)
A16: Wk 11 | B16: MP 2 | C16: Nov 09 – Nov 13, 2026 ⚠ Wed 11/11 Veterans Day — Schools Closed | E16: =HYPERLINK("https://drive.google.com/drive/folders/1ozCBpU95YpTaRSw14x4-u4Nlmci2ZTAq","◆ Cycle 08 · Cells & Organelles Intro to Cells (Intro to Cells VT · Learn.Genetics Cell Size & Scale) VT Folder") -> ◆ Cycle 08 · Cells & Organelles Intro to Cells (Intro to Cells VT · Learn.Genetics Cell Size & Scale) VT Folder | F16: 11/9 Intro to Cells lesson · Cell Size & Scale fiddle (short) 📝 DRAFT.Population Ecology due 11/9 | G16: 11/11 OFF — Veterans Day (Schools Closed) | H16: 11/13 History of cell discovery / cell theory timeline (long) (moved from Wed 11/11 — Veterans Day) Notes.Intro to Cells due 11/13 | I16: 🍗 Muscles (System) ↗ — Activities — (CA#M1 sarcomere = the contractile unit) • Fiddle (slides): GetBodySmart sliding-filament animation • Short: label-the-sarcomere — Z-line / A-band / I-band (CA#M1) • Long: Chicken Wing Dissection — muscle→fascicle→fiber→sarcomere hierarchy • Alts: Tom (DMD) case / "rubber-band sarcomere" build / Label Muscle Structure + Sarcomere coloring (open-book ref) | J16: 11/10 Tue: #M1 Lesson: Muscular System · Case: Tom (DMD) | K16: 11/12 Thu: Lab: Chicken Wing Dissection (see the hierarchy) | L16: 11/13 Fri: #M1 Sarcomere = the contractile unit · Open-book ref: Label Muscle Structure, Sarcomere coloring | M16: Arson VT Folder | N16: 11/9 Arson — lesson + short (Willingham) | O16: 11/11 OFF — Veterans Day (Schools Closed) | P16: 11/13 Arson evidence activity · 📝 Notes due (moved from Wed 11/11 — Veterans Day)
A17: Wk 12 | B17: MP 2 | C17: Nov 16 – Nov 20, 2026 | E17: =HYPERLINK("https://drive.google.com/drive/folders/1ozCBpU95YpTaRSw14x4-u4Nlmci2ZTAq","◆ Cycle 08 · Cells & Organelles Cell Organelles (Cell Organelles VT · BioMan Cell Explorer) VT Folder") -> ◆ Cycle 08 · Cells & Organelles Cell Organelles (Cell Organelles VT · BioMan Cell Explorer) VT Folder | F17: 11/16 Cell Organelles lesson · BioMan Cell Explorer fiddle (short) 📝 DRAFT.Intro to Cells due 11/16 | G17: 11/18 Organelles Stations (plant vs animal sort, labeling) (long) Notes.Cell Organelles due 11/18 | H17: 11/20 Finish labs/activities | I17: 🍗 Muscles (System) (cont.) ↗ — Activities — (CA#M2 sliding filament → #M3–4 NMJ & dystrophin → #M5 NMJ poisons) • Fiddle (slides): BioMan / PhET muscle-contraction sim • Short: sliding-filament sequence sort (CA#M2) • Long: The Gene Doctors (DMD) — NMJ & dystrophin (CA#M3–4) • Alts: #M5 NMJ-poison "predict the effect" (curare/botulinum/organophosphate) / Tired Swimmer (myasthenia) case / NMJ diagram label | J17: 11/17 Tue: #M2 Sliding Filament Model — how a muscle shortens | K17: 11/19 Thu: #M3–4 NMJ & dystrophin — Video: The Gene Doctors (DMD) | L17: 11/20 Fri: #M5 NMJ poisons — predict the effect · Case: The Tired Swimmer 🦄 | M17: Ballistics VT Folder | N17: 11/16 Ballistics — lesson + short (St. Valentine's Day Massacre) 📝 DRAFT.Arson due 11/16 | O17: 11/18 Ballistics matching activity · 📝 Notes due | P17: 11/20 Catch-up / flex (EOW)
A18: Wk 13 | B18: MP 2 | C18: Nov 23 – Nov 27, 2026 ⚠ Teacher in-service Mon–Wed (no students) · Thanksgiving Thu–Fri | E18: No classes — teacher in-service Mon–Wed + Thanksgiving Thu–Fri Folder | F18: 11/23 OFF — Teacher in-service (no students) | G18: 11/25 OFF — Teacher in-service (no students) | H18: 11/27 OFF — Thanksgiving | I18: No classes — teacher in-service Mon–Wed + Thanksgiving Thu–Fri | J18: 11/24 OFF — Teacher in-service (no students) | K18: 11/26 OFF — Thanksgiving | L18: 11/27 OFF — Thanksgiving | M18: Blood Evidence (Part 1) VT Folder | N18: 11/23 OFF — Teacher in-service (no students) | O18: 11/25 OFF — Teacher in-service (no students) | P18: 11/27 OFF — Thanksgiving
A19: Wk 14 | B19: MP 2 | C19: Nov 30 – Dec 04, 2026 | E19: =HYPERLINK("https://drive.google.com/drive/folders/1BsqqCAa467Hs8Rkaenoa1z7kZT84_1Mo","◆ Cycle 09 · Membrane & Transport Cell Membrane (Cell Membrane Lesson · BioMan Cell Defense) VT Folder") -> ◆ Cycle 09 · Membrane & Transport Cell Membrane (Cell Membrane Lesson · BioMan Cell Defense) VT Folder | F19: 11/30 Cell Membrane lesson + Cell Defense fiddle (short) 📝 DRAFT.Cell Organelles due 11/30 | G19: 12/2 Membrane Bubble Lab (long) Notes.Cell Membrane due 12/2 | H19: 12/4 Finish labs/activities | I19: 🍗 Muscles (Naming) ↗ — Activities — • Fiddle (slides): GetBodySmart muscle-naming map • Short: muscle-naming logic drill (shape/location/action — trapezius/rhomboid/serratus) • Long: muscle-groups open-book practice + Muscle Anatomy coloring • Alts: Mystery of Muscle Weakness case / origin–insertion–action table / Kahoot muscle-naming review | J19: 12/1 Tue: Muscle naming & groups (open-book practice) · ref: Muscle Anatomy coloring | K19: 12/3 Thu: Case: Mystery of Muscle Weakness | L19: 12/4 Fri: Open-book practice | M19: Blood Evidence (Part 2) VT Folder | N19: 11/30 Blood L1: Serology / Typing — lesson + short 📝 DRAFT.Ballistics due 11/30 | O19: 12/2 Blood typing lab · 📝 Notes due | P19: 12/4 Catch-up / flex (EOW)
A20: Wk 15 | B20: MP 2 | C20: Dec 07 – Dec 11, 2026 ⚠ Fri 12/11 In-Service — Schools Closed | E20: =HYPERLINK("https://drive.google.com/drive/folders/1BsqqCAa467Hs8Rkaenoa1z7kZT84_1Mo","◆ Cycle 09 · Membrane & Transport Cell Transport (Cell Transport Lesson · PhET Membrane Transport + BioMan Osmosis) VT Folder") -> ◆ Cycle 09 · Membrane & Transport Cell Transport (Cell Transport Lesson · PhET Membrane Transport + BioMan Osmosis) VT Folder | F20: 12/7 Cell Transport lesson · PhET Membrane Transport fiddle (short) 📝 DRAFT.Cell Membrane due 12/7 | G20: 12/9 Osmosis lab (egg/potato) + BioMan Osmosis (long) Notes.Cell Transport due 12/9 | H20: 12/11 OFF — In-Service (Schools Closed) | I20: 🍗 Muscles (Naming) (cont.) ↗ — Activities — • Fiddle (slides): muscle-ID speed round • Short: open-book review circuit • Long: 📝 UNIT EXAM — Muscular System • Alts: flex/catch-up lab make-ups / peer quiz relay / cumulative muscle map | J20: 12/8 Tue: Open-book review | K20: 12/10 Thu: 📝 UNIT EXAM — Muscular System | L20: 12/11 OFF — In-Service (Schools Closed) | M20: DNA Profiling (Part 1) VT Folder | N20: 12/7 Blood L2–3: Spatter — lesson + short 📝 DRAFT.Blood Evidence L1: Serology / Blood Typing due 12/7 | O20: 12/9 Spatter angle & area-of-origin lab · 📝 Notes due | P20: 12/11 OFF — In-Service (Schools Closed)
A21: Wk 16 | B21: MP 2 | C21: Dec 14 – Dec 18, 2026 | E21: =HYPERLINK("https://drive.google.com/drive/folders/1lSREsE87lV-dqy8foAktSXf-uHABeqsN","◆ Cycle 10 · Enzymes Enzymes (Enzymes Lesson · BioMan Enzymatic) VT Folder") -> ◆ Cycle 10 · Enzymes Enzymes (Enzymes Lesson · BioMan Enzymatic) VT Folder | F21: 12/14 Enzymes lesson · BioMan Enzymatic fiddle (short) 📝 DRAFT.Cell Transport due 12/14 | G21: 12/16 Enzyme lab (toothpickase / liver-catalase) (long) Notes.Enzymes due 12/16 | H21: 12/18 Finish labs/activities | I21: Nervous System ↗ — Activities — (CA#N1 organization → #N2–3 myelin/demyelination → #N4 synapse) • Fiddle (slides): GetBodySmart / BioMan action-potential animation • Short: MS (Izzy) case — CNS/PNS organization (CA#N1) • Long: myelin & demyelination model (CA#N2–3) · Neuroglia (open-book ref) • Alts: #N4 synapse "pass the signal" model / Concussions case / label-the-neuron | J21: 12/15 Tue: #N1 Lesson: Nervous System · Case: MS (Izzy) — organization | K21: 12/17 Thu: #N2–3 Myelin & demyelination (MS) · Neuroglia (open-book ref) | L21: 12/18 Fri: #N4 The synapse · Case Study: Concussions 🦄 | M21: DNA Profiling (Part 2) VT Folder | N21: 12/14 DNA Profiling L1 — lesson + short (Colin Pitchfork) 📝 DRAFT.Blood Evidence L2–L3: Spatter due 12/14 | O21: 12/16 DNA profiling activity · 📝 Notes due | P21: 12/18 Catch-up / flex (EOW)
A22: Wk 16b | B22: MP 2 | C22: Dec 21 – Dec 22, 2026 ⚠ Mon–Tue only · Winter break begins Wed 12/23 | E22: Semester 1 catch-up / grading — no new content | F22: 12/21 Buffer: catch-up, late/missing work, notebook check · no new content | G22: 12/23 OFF — Winter Break begins | H22: 12/25 OFF — Winter Break | I22: Semester 1 catch-up / grading — no new content | J22: 12/22 Buffer: catch-up, lab make-ups, grading · no new content | K22: 12/24 OFF — Winter Break | L22: 12/25 OFF — Winter Break | M22: Semester 1 catch-up / grading — no new content | N22: 12/21 Buffer: catch-up, late/missing work · no new content | O22: 12/23 OFF — Winter Break begins | P22: 12/25 OFF — Winter Break
A23: Wk 17 | B23: MP 2 | C23: Jan 04 – Jan 08, 2027 ⚠ Winter break Dec 23 – Jan 3 | E23: ◆ Enrichment → folds into Cycle 06 (Respiration & Fermentation) Cellular Respiration & Glycolysis (Cellular Respiration revised · BioMan Photo & Resp) VT Folder | F23: 1/4 Cellular Respiration lesson · BioMan Photo & Resp fiddle (short) 📝 DRAFT.Enzymes due 1/4 | G23: 1/6 Respiration graphic organizer / stations (long) Notes.Cellular Respiration due 1/6 | H23: 1/8 Finish labs/activities | I23: Nervous System (cont.) ↗ — Activities — (CA#N5 drugs hijack the synapse) • Fiddle (slides): Mouse Party (Learn.Genetics) — drugs at the synapse • Short: Substance Abuse & Teens — synapse hijack (CA#N5) • Long: Brain Dissection (sheep) + Mini Mental State Exam • Alts: Cranial Nerves (open-book ref) / Brain–Synapse coloring / Review Guide before Unit Exam | J23: 1/5 Tue: #N5 Drugs hijack the synapse — Substance Abuse & Teens | K23: 1/7 Thu: Brain (condensed): Brain Dissection lab + Mini Mental State · Cranial Nerves = open-book ref | L23: 1/8 Fri: 📝 UNIT EXAM — Nervous System · ref: Brain/Synapse coloring, Cranial Nerves, Review Guide | M23: DNA Profiling (Part 3) & Fibers VT Folder | N23: 1/4 DNA Profiling L2: match probability — lesson + short 📝 DRAFT.DNA Profiling L1 due 1/4 | O23: 1/6 Virtual gel electrophoresis · 📝 Notes due | P23: 1/8 Catch-up / flex (EOW)
A24: Wk 18 | B24: MP 2 | C24: Jan 11 – Jan 15, 2027 | E24: =HYPERLINK("https://drive.google.com/drive/folders/1LltOdMoB_7F9KQC1rDgjQg77S8sVvkf3","◆ Cycle 11 · Cell Cycle → Cancer Cell Regulation & Cancer (Cell Regulation and Cancer VT · HHMI Cell Cycle & Cancer) VT Folder") -> ◆ Cycle 11 · Cell Cycle → Cancer Cell Regulation & Cancer (Cell Regulation and Cancer VT · HHMI Cell Cycle & Cancer) VT Folder | F24: 1/11 Cancer lesson · HHMI Cell Cycle & Cancer fiddle (short) 📝 DRAFT.Cellular Respiration due 1/11 | G24: 1/13 Cancer Cells Research Stations / Mitosis–Cancer case study (long) Notes.Cell Regulation & Cancer due 1/13 | H24: 1/15 Finish labs/activities | I24: Semester 1 Final Exam Review ↗ — Activities — • Fiddle (slides): cumulative Kahoot (systems so far) • Short: unit-by-unit "one big idea" recall lap • Long: 📝 SEMESTER 1 FINAL EXAM • Alts: homeostasis-throughline concept map / station review (skeletal/muscular/nervous) / open-book guide | J24: 1/12 Tue: Final Exam Review | K24: 1/14 Thu: 📝 SEMESTER 1 FINAL EXAM | M24: Fibers VT Folder | N24: 1/11 Fibers — lesson + short (Wayne Williams) 📝 DRAFT.DNA Profiling L2: match probability due 1/11 | O24: 1/13 Fiber burn / microscopy lab · 📝 Notes due | P24: 1/15 Catch-up / flex (EOW)
A25: ──── MP 3 ────────────────────────────────────────────────────────────
A26: Wk 19 | B26: MP 3 | C26: Jan 18 – Jan 22, 2027 ⚠ Mon 01/18 MLK Day | E26: =HYPERLINK("https://drive.google.com/drive/folders/1LltOdMoB_7F9KQC1rDgjQg77S8sVvkf3","◆ Cycle 11 · Cell Cycle → Cancer The Cell Cycle · VT ✓ (The Cell Cycle VT · HHMI Cell Cycle & Cancer) VT Folder") -> ◆ Cycle 11 · Cell Cycle → Cancer The Cell Cycle · VT ✓ (The Cell Cycle VT · HHMI Cell Cycle & Cancer) VT Folder | F26: 1/18 OFF | G26: 1/20 Cell Cycle Lesson (VT) + fiddle · Notes.The Cell Cycle due 1/20 — Activities — • Fiddle (slides): Mitosis Mover (BioMan) • Short: Cell‑Cycle Card Sort • Long: Eukaryotic Cell Cycle and Cancer Click & Learn • Alts: Cell Cycle Simulation (Learn.Genetics, University of Utah) – https://learn.genetics.utah.edu/content/cells/cellcycle/ – lets students toggle between interphase and mitosis on a single slide. / Cell‑Cycle Timeline Worksheet (Science Buddies) – https://www.sciencebuddies.org/science-fair-projects/references/cell-cycle-timeline – students place events on a timeline, encouraging reasoning about order and purpose. / Stem‑Cell Differentiation Lab (HHMI) – https://www.biointeractive.org/classroom-resources/stem-cell-differentiation – students model how cell‑cycle timing influences stem‑cell fate, linking division to specialization. 📝 DRAFT.Cell Regulation & Cancer due 1/20 (Mon off) | H26: 1/22 (A) Onion root tip mitosis lab / cell-cycle stations · finish labs/activities | I26: Forensics Mini Unit (A&P) ↗ — Activities — • Post-S1-final forensics crossover — materials in the 'Week 19 - Forensics Mini Unit' folder • Activity menu to be built from the folder's contents (confirm forensics scope) | M26: Hair VT Folder | N26: 1/18 OFF — MLK Day | O26: 1/20 Fingerprints — lesson (Mayfield) (moved from Mon 1/18 — MLK Day) + Dusting & lifting latent prints · 📝 Notes due 📝 DRAFT.Fibers due 1/20 (Mon off) | P26: 1/22 Catch-up / flex (EOW)
A27: Wk 20 | B27: MP 3 | C27: Jan 25 – Jan 29, 2027 | E27: =HYPERLINK("https://drive.google.com/drive/folders/1XOyYlAk2a5yJkWksIPv6bAtdB5l84Bis","◆ Cycle 12 · Reproduction & Meiosis Asexual & Sexual Reproduction · VT ✓ (Asexual & Sexual Reproduction VT · BioMan Snurfle Meiosis) VT Folder") -> ◆ Cycle 12 · Reproduction & Meiosis Asexual & Sexual Reproduction · VT ✓ (Asexual & Sexual Reproduction VT · BioMan Snurfle Meiosis) VT Folder | F27: 1/25 IN-SERVICE | G27: 1/27 Asexual reproduction types stations (fission/budding/fragmentation) · Notes.Asexual & Sexual Reproduction due 1/27 — Activities — • Fiddle (slides): Snurfle Meiosis (BioMan) • Short: Think‑Pair‑Share: Clones vs. Hybrids • Long: Starfish Regeneration Lab • Alts: HHMI BioInteractive video: "Sexual vs. Asexual Reproduction" (online video that can be embedded on a slide). / 5E Lesson “Reproduction Think Cards” – short card‑based activity where groups sort scenarios into asexual or sexual categories and justify their choices. / AACT Aphid Life‑Cycle Investigation – students raise aphids under different conditions to see how they switch between asexual and sexual reproduction. 📝 DRAFT.The Cell Cycle due 1/27 (Mon off) | H27: 1/29 Finish labs/activities | I27: Senses ↗ — Activities — (CA#S1 receptor types → #S2 pain) • Fiddle (slides): receptor-type sorting interactive • Short: Lab Stations on Senses — classify receptors (CA#S1) • Long: Two-Point Touch Discrimination — receptor density (CA#S1) • Alts: #S2 Pain — ice demo + FLACC scale / Pain in the Rear case / Label the Ear (open-book ref) | J27: 1/26 Tue: #S1 Lesson: Sensory Perception · Lab Stations on Senses (receptor types) | K27: 1/28 Thu: #S1 Two-Point Touch Discrimination (lab — receptor density) · ref: Label the Ear | L27: 1/29 Fri: #S2 Pain — Ice demo + Case: Pain in the Rear (FLACC scale) | M27: Unit 2 Review & Exam Folder | N27: 1/25 OFF — In-Service | O27: 1/27 Hair — lesson (Santae Tribble) (moved from Mon 1/25 — in-service) + Hair microscopy lab · 📝 Notes due 📝 DRAFT.Fingerprints due 1/27 (Mon off) | P27: 1/29 Catch-up / flex (EOW)
A28: Wk 21 | B28: MP 3 | C28: Feb 01 – Feb 05, 2027 | E28: =HYPERLINK("https://drive.google.com/drive/folders/1QUooI_qUo2iLDJCr5gaBdQBc0QHPzxgx","◆ Cycle 16 · Mutations & Gene Expression Stem Cell Differentiation · VT ✓ (Stem Cell Differentiation VT · HHMI) VT Folder") -> ◆ Cycle 16 · Mutations & Gene Expression Stem Cell Differentiation · VT ✓ (Stem Cell Differentiation VT · HHMI) VT Folder | F28: 2/1 Stem cell differentiation reading / case study — Activities — • Fiddle (slides): BioMan Cell Specialization Game • Short: HHMI BioInteractive – Cancer and Cell Fate in the Intestinal Epithelium • Long: Morgridge Institute Directed Differentiation Activity • Alts: Use a Kahoot quiz titled “Stem Cell Potency Quick‑Fire” (source: web) to test key concepts in real time. / Conduct a Think‑Pair‑Share using the Sanford PROMISE Immortal Cells Cell Differentiation Activity (source: Sanford PROMISE) to discuss epigenetic signals. / Run the PBS NOVA "Stem Cells Breakthrough" classroom activity (source: PBS NOVA) where students build clay models of differentiated tissues and map lineage pathways. 📝 DRAFT.Asexual & Sexual Reproduction due 2/1 | G28: 2/3 Stem cell ethics discussion (claim–evidence) · Notes.Stem Cell Differentiation due 2/3 | H28: 2/5 Finish labs/activities | I28: Senses (cont.) ↗ — Activities — (CA#S3–4 hearing chain + eye) • Fiddle (slides): GetBodySmart ear/eye interactive • Short: hearing-chain sequence sort (CA#S3) • Long: Cow Eye Dissection (CA#S4) • Alts: Molly/Leber case (gene→phenotype) / Eye–Ear coloring (open-book ref) / review before Unit Exam | J28: 2/2 Tue: #S3–4 Hearing chain + Eye — Cow Eye Dissection | K28: 2/4 Thu: Eye/Leber case (Molly): gene → phenotype [Eye companion deck] · ref: Eye/Ear coloring | L28: 2/5 Fri: Open-book review · 📝 UNIT EXAM — Senses | M28: Unit 2 Review & Assessment Folder | N28: 2/1 Unit 2 — Review 📝 DRAFT.Hair due 2/1 | O28: 2/3 📝 Unit 2 Assessment | P28: 2/5 Catch-up / flex (EOW)
A29: Wk 22 | B29: MP 3 | C29: Feb 08 – Feb 12, 2027 | E29: =HYPERLINK("https://drive.google.com/drive/folders/19wtWM4tfDvTtnHuNHGL0aHwrmZFHpSO8","◆ Cycle 13 · Mendelian Genetics Introduction to Heredity · VT ✓ (Introduction to Heredity · VT built) VT Folder") -> ◆ Cycle 13 · Mendelian Genetics Introduction to Heredity · VT ✓ (Introduction to Heredity · VT built) VT Folder | F29: 2/8 Intro to Heredity Lesson — Activities — • Fiddle (slides): Monster Genetics Simulation • Short: Pedigree Analysis Worksheet • Long: Inheritance of Lactose Intolerance (HHMI BioInteractive) • Alts: Snurfle Meiosis and Genetics game (BioMan) – an interactive quiz on meiosis and trait inheritance. / Design "Y'er Genes" activity (Science Buddies) – students model DNA mutations and predict phenotypic changes. / University of Utah Teach.Genetics – Generations of Traits pom‑pom activity – hands‑on exploration of trait inheritance across multiple generations. 📝 DRAFT.Stem Cell Differentiation due 2/8 | G29: 2/10 Class trait inventory / family traits activity · Notes.Introduction to Heredity due 2/10 | H29: 2/12 IN-SERVICE 2/12 | I29: Endocrine System ↗ — Activities — (CA#E1–2 messengers & feedback) • Fiddle (slides): hormone-target "lock & key" interactive • Short: Timothy case — messengers & feedback (CA#E1–2) • Long: HASPI Stress Response Lab (cortisol/adrenaline) • Alts: negative vs positive feedback sort / Ghrelin Demo (article) / Endocrine Concept Map (open-book ref) | J29: 2/9 Tue: #E1–2 Lesson: Endocrine · Case: Timothy — messengers & feedback | K29: 2/11 Thu: #E2 HASPI Stress Response Lab (cortisol/adrenaline) + #E2 Negative vs positive feedback · Ghrelin Demo (article) (moved from Fri 2/12 — in-service) | L29: 2/12 OFF — In-Service | M29: Cold Case Synthesis (Unit 2 Capstone) Folder | N29: 2/8 Mon: Cold-case file drop — integrate Unit 2 evidence (arson, ballistics, blood, DNA, fibers, prints, hair); build the case, verdict withheld | O29: 2/10 Wed: Evidence-reliability audit — which forensics hold up vs. overstate? · team findings + reveal | P29: 2/12 OFF — In-Service
A30: Wk 23 | B30: MP 3 | C30: Feb 15 – Feb 19, 2027 ⚠ Mon 02/15 Presidents' Day | E30: =HYPERLINK("https://drive.google.com/drive/folders/19wtWM4tfDvTtnHuNHGL0aHwrmZFHpSO8","◆ Cycle 13 · Mendelian Genetics Intro to Genetics & Mendel · VT ✓ (Mendelian Genetics Lesson · Snurfle Meiosis & Genetics) VT Folder") -> ◆ Cycle 13 · Mendelian Genetics Intro to Genetics & Mendel · VT ✓ (Mendelian Genetics Lesson · Snurfle Meiosis & Genetics) VT Folder | F30: 2/15 OFF | G30: 2/17 Mendelian Genetics Lesson + Snurfle Genetics fiddle · Notes.Mendelian Genetics due 2/17 — Activities — • Fiddle (slides): Monster Genetics • Short: Punnett Square Practice (Stickelback Trait) • Long: Mendelian Genetics, Probability, Pedigrees, and Chi‑Square Statistics • Alts: Snurfle Meiosis and Genetics (BioMan) – https://www.biomanbio.com/Genetics/SnurfleMeiosis.htm – lets students visualize meiosis and allele separation in a short interactive / BioMan Genetics Quiz – https://www.biomanbio.com/Genetics/GeneticsQuiz.htm – a rapid‑fire quiz that forces students to think through monohybrid cross outcomes / Science Buddies Mendelian Genetics Lab – https://www.sciencebuddies.org/science-fair-projects/project-ideas/Genetics_p025/biology – a hands‑on pea‑plant experiment guiding students through setting up crosses, recording data, and analyzing ratios 📝 DRAFT.Introduction to Heredity due 2/17 (Mon off) | H30: 2/19 (B) Monster Genetics / Mendel pea-cross activity · finish labs/activities | I30: Endocrine System (cont.) ↗ — Activities — (CA#E4 hyper/hypo disorders) • Fiddle (slides): insulin/glucagon feedback simulator • Short: hyper/hypo disorder match (CA#E4) • Long: glucose homeostasis (insulin/glucagon) & diabetes investigation • Alts: Achondroplasia & Gene Therapy (bioethics) / Vocab Matching + Review Guide / open-book review before Unit Exam | J30: 2/16 Tue: #E4 Hyper/hypo disorders — Achondroplasia & Gene Therapy (bioethics) | K30: 2/18 Thu: Glucose homeostasis (insulin/glucagon) & diabetes · ref: Endocrine Concept Map | L30: 2/19 Fri: Open-book review · 📝 UNIT EXAM — Endocrine · ref: Vocab Matching, Review Guide | M30: Forensic Pathology & Expert in Court (Bridge to Unit 3) Folder | N30: 2/15 OFF — Presidents Day | O30: 2/17 Wed: Intro to the Medical Examiner & forensic pathology — what an autopsy can/can't answer (bridge to Death unit) | P30: 2/19 Fri: The forensic expert in court — testimony, junk science & the 'CSI effect'
A31: Wk 24 | B31: MP 3 | C31: Feb 22 – Feb 26, 2027 | E31: =HYPERLINK("https://drive.google.com/drive/folders/19wtWM4tfDvTtnHuNHGL0aHwrmZFHpSO8","◆ Cycle 13 · Mendelian Genetics Genetics Continued: Punnett Squares · VT ✓ (genetics_with_vt_inserts · Pedigrees · Complex Inheritance) VT Folder") -> ◆ Cycle 13 · Mendelian Genetics Genetics Continued: Punnett Squares · VT ✓ (genetics_with_vt_inserts · Pedigrees · Complex Inheritance) VT Folder | F31: 2/22 Genetics Continued (VT) + Punnett practice — Activities — • Fiddle (slides): Pedigree Analysis Game • Short: Blue Fugates Case Discussion • Long: Science Buddies: Methemoglobinemia Pedigree Lab • Alts: Genetics Monster Builder (BioMan) – interactive drag‑and‑drop to create parent monsters and predict offspring traits; reinforces Punnett square thinking on a slide. / Quick Think‑Pair‑Share: Predicting offspring skin color for the Blue Fugates – a 5‑minute classroom prompt that asks pairs to calculate probabilities and justify carrier status (source: web). / HHMI BioInteractive: Sickle Cell Disease – Extended Lab – students model a real‑world recessive disorder, build pedigrees, and perform chi‑square analysis (source: HHMI). 📝 DRAFT.Mendelian Genetics due 2/22 | G31: 2/24 Punnett square stations + Pedigrees · Notes.Genetics Continued due 2/24 | H31: 2/26 Finish labs/activities | I31: Blood and Immune System ↗ — Activities — • Fiddle (slides): blood-cell ID interactive (RBC/WBC/platelets) • Short: Ian (Cooley's Anemia) case • Long: Hematocrit Investigation • Alts: WBC & immunity (VT) / Sickle Cell + Survival of the Sickest (evolution link) / Blood Concept Map | J31: 2/23 Tue: Lesson: Blood Cells (RBC/WBC/Platelets) · Case: Ian (Cooley's Anemia) | K31: 2/25 Thu: WBC & immunity (VT) · Hematocrit Investigation | L31: 2/26 Fri: Genetics: Sickle Cell + Survival of the Sickest 🦄 (evolution) | M31: Introduction to Toxicology & Toxicology-Drug Schedules VT Folder | N31: 2/22 Toxicology: Introduction — lesson + short (Lafarge) | O31: 2/24 LD50 “dose makes the poison” · 📝 Notes due | P31: 2/26 Catch-up / flex (EOW)
A32: Wk 25 | B32: MP 3 | C32: Mar 01 – Mar 05, 2027 | E32: ◆ Enrichment → folds into Cycle 13 (Mendelian Genetics) Dihybrid Crosses · VT ✓ (Mendels Laws & Dihybrid · Snurfle Meiosis 2) VT Folder | F32: 3/1 Dihybrid Lesson + Snurfle Meiosis 2 fiddle — Activities — • Fiddle (slides): Snurfle Meiosis and Genetics 2: Diversity and Dihybrid Crosses • Short: Modeling Independent Assortment and Dihybrid Crosses • Long: The Teosinte Hypothesis • Alts: Genetics Games – Dihybrid Cross Challenge (Science Buddies) – an online interactive that lets students drag‑and‑drop alleles into a 16‑square grid. / Think‑Pair‑Share: Predicting Dihybrid Ratios – students first predict outcomes individually, then discuss in pairs, and finally share with the class. / Laboratory Dihybrid Cross with Fast‑Growing Peas – students set up real monohybrid and dihybrid crosses, grow plants, and record phenotypic ratios over several weeks. 📝 DRAFT.Genetics Continued due 3/1 | G32: 3/3 Dihybrid cross practice / 9:3:3:1 ratios · Notes.Dihybrid Crosses due 3/3 | H32: 3/5 Finish labs/activities | I32: Blood and Immune System (cont.) ↗ — Activities — • Fiddle (slides): blood-typing antigen/antibody sim • Short: Blood Typing (VT) — antigens & compatibility • Long: Blood Typing Lab (+ simulated blood) • Alts: Alpha Gal Syndrome case / compatibility grid / Blood Case Studies | J32: 3/2 Tue: Blood Typing (VT) — antigens & compatibility | K32: 3/4 Thu: Lab: Blood Typing Lab (+ Simulated Blood) | L32: 3/5 Fri: Case: Alpha Gal Syndrome 🦄 / Blood Case Studies | M32: Toxicology and Forensics VT Folder | N32: 3/1 Toxicology: Effect of Drugs — lesson + short 📝 DRAFT.Toxicology: Introduction due 3/1 | O32: 3/3 Drug-schedule activity · 📝 Notes due | P32: 3/5 Catch-up / flex (EOW)
A33: Wk 26 | B33: MP 3 | C33: Mar 08 – Mar 12, 2027 ⚠ Wed 3/10 In-Service — Schools Closed | E33: =HYPERLINK("https://drive.google.com/drive/folders/1flXCm6TJKiaenHyVoyBmZVbLHlZDRvNn","◆ Cycle 14 · DNA Structure & Replication DNA Structure · VT ✓ (DNA Structure — VT Inserts) VT Folder") -> ◆ Cycle 14 · DNA Structure & Replication DNA Structure · VT ✓ (DNA Structure — VT Inserts) VT Folder | F33: 3/8 DNA Structure Lesson (VT) — Activities — • Fiddle (slides): BioMan DNA Structure Builder • Short: HHMI DNA Modeling Card Activity • Long: Science Buddies Candy DNA Lab • Alts: Interactive DNA Zipper Mini‑Game (web) – a simple browser game that lets students drag and drop bases to form a helix / Think‑Pair‑Share: Mutation Impacts Worksheet (web) – students analyze scenarios of harmful vs. beneficial mutations / Case Study: The Human Genome Project (web) – students explore real data, genome size, and ethical considerations 📝 DRAFT.Dihybrid Crosses due 3/8 | G33: 3/10 OFF — In-Service (Schools Closed) | H33: 3/12 DNA model build (paper / candy) (moved from Wed 3/10 — in-service) Notes.DNA Structure due 3/12 | I33: Blood and Immune System (cont.) ↗ — Activities — • Fiddle (slides): HHMI immune-response animation • Short: Man With the Golden Arm — immune defense • Long: Hemophilia + blood feedback-loop investigation • Alts: WBC Chart / Concept Map / Study Guide — open-book review before Unit Exam | J33: 3/9 Tue: Immune defense — Man With the Golden Arm 🦄 | K33: 3/11 Thu: Genetics: Hemophilia · Blood Feedback Loop | L33: 3/12 Fri: Open-book review · 📝 UNIT EXAM — Blood & Immune · ref: Concept Map, WBC Chart, Study Guide | M33: Toxicology Review & Assessment Folder | N33: 3/8 Toxicology — Review 📝 DRAFT.Toxicology: The Effect of Drugs due 3/8 | O33: 3/10 OFF — In-Service (Schools Closed) | P33: 3/12 📝 Toxicology Assessment (moved from Wed 3/10 — in-service)
A34: Wk 27 | B34: MP 3 | C34: Mar 15 – Mar 19, 2027 | E34: =HYPERLINK("https://drive.google.com/drive/folders/1flXCm6TJKiaenHyVoyBmZVbLHlZDRvNn","◆ Cycle 14 · DNA Structure & Replication DNA Replication · VT ✓ (DNA Replication VT) VT Folder") -> ◆ Cycle 14 · DNA Structure & Replication DNA Replication · VT ✓ (DNA Replication VT) VT Folder | F34: 3/15 DNA Replication Lesson (VT) — Activities — • Fiddle (slides): BioMan DNA Replication Interactive • Short: HHMI Think‑Pair‑Share: Enzyme Order Card Sort • Long: Science Buddies Meselson‑Stahl Pulse‑Chase Lab • Alts: AACT DNA Replication Game / Web‑based DNA Replication Think‑Quiz (Quizizz) / Pipe‑Cleaner DNA Model Activity (Science Buddies) 📝 DRAFT.DNA Structure due 3/15 | G34: 3/17 DNA replication modeling activity · Notes.DNA Replication due 3/17 | H34: 3/19 Finish labs/activities | I34: Heart and Circulatory System ↗ — Activities — • Fiddle (slides): GetBodySmart heart / blood-flow animation • Short: Aortic Stenosis (Lucas) — structure→function • Long: Heart Dissection (sheep) • Alts: A Tiny Heart / Heart of a Swimmer case / trace-a-drop blood-flow path / Label the Heart (open-book ref) | J34: 3/16 Tue: Lesson: Cardiovascular System (VT) · Case: Aortic Stenosis (Lucas) | K34: 3/18 Thu: Lab: Heart Dissection | L34: 3/19 Fri: Case: A Tiny Heart + Heart of a Swimmer 🦄 · ref: Label the Heart | M34: Introduction to Death & What is Death VT Folder | N34: 3/15 What is Death? — lesson + short (Schiavo/McMath) | O34: 3/17 Class debate: defining death · 📝 Notes due | P34: 3/19 Catch-up / flex (EOW)
A35: ──── MP 4 ────────────────────────────────────────────────────────────
A36: Wk 28 | B36: MP 4 | C36: Mar 22 – Mar 26, 2027 ⚠ Fri 03/26 Schools Closed | E36: =HYPERLINK("https://drive.google.com/drive/folders/1XOyYlAk2a5yJkWksIPv6bAtdB5l84Bis","◆ Cycle 12 · Reproduction & Meiosis Meiosis and Sexual Reproduction · VT ✓ (The Process of Meiosis — VT Inserts) VT Folder") -> ◆ Cycle 12 · Reproduction & Meiosis Meiosis and Sexual Reproduction · VT ✓ (The Process of Meiosis — VT Inserts) VT Folder | F36: 3/22 Meiosis VT (3-Tier) + Snurfle Meiosis fiddle · Day-1 short: mitosis-vs-meiosis compare 📝 DRAFT.DNA Replication due 3/22 | G36: 3/24 Day-2 long: chromosome modeling — crossing over & independent assortment Notes.Meiosis due 3/24 | H36: 3/26 OFF — Schools Closed | I36: Heart & Circulatory System (cont.) ↗ — Activities — • Fiddle (slides): ECG / pacemaker interactive • Short: Cardiac Cycle (VT) — pacemaker / ECG / BP • Long: Measuring Blood Pressure lab • Alts: pulse-pressure prediction / Label Circulatory System (open-book ref) / open-book review before Unit Exam | J36: 3/23 Tue: Cardiac Cycle (VT) — pacemaker / ECG / blood pressure + Lab: Measuring Blood Pressure | K36: 3/25 Thu: 📝 UNIT EXAM — Heart & Circulatory · Open-book review · ref: Label Circulatory System | L36: 3/26 OFF — Schools Closed | M36: Stages of Decomposition & The Body Farm Folder | N36: 3/22 Stages of Decomposition — lesson + short: decomposition-stage sort 📝 DRAFT.What is Death? due 3/22 | O36: 3/24 The Body Farm (forensic taphonomy) case study · 📝 Notes due | P36: 3/26 OFF — Schools Closed
A37: Wk 29 | B37: MP 4 | C37: Mar 29 – Apr 02, 2027 ⚠ Spring Break | E37: Spring Break | F37: 3/29 OFF — Spring Break | G37: 3/31 OFF — Spring Break | H37: 4/2 OFF — Spring Break | I37: Spring Break | J37: 3/30 OFF — Spring Break | K37: 4/1 OFF — Spring Break | L37: 4/2 OFF — Spring Break | M37: Spring Break | N37: 3/29 OFF — Spring Break | O37: 3/31 OFF — Spring Break | P37: 4/2 OFF — Spring Break
A38: Wk 30 | B38: MP 4 | C38: Apr 05 – Apr 09, 2027 | E38: =HYPERLINK("https://drive.google.com/drive/folders/1RKFet7ov0Pfu6kbG1mDfnQKWzGpFHJXA","◆ Cycle 15 · Protein Synthesis Genes and Chromosomes · VT ✓ (Genes and Chromosomes VT — DNA→gene→chromosome, locus, alleles) VT Folder") -> ◆ Cycle 15 · Protein Synthesis Genes and Chromosomes · VT ✓ (Genes and Chromosomes VT — DNA→gene→chromosome, locus, alleles) VT Folder | F38: 4/5 Genes & Chromosomes VT (3-Tier) + Tour of the Basics fiddle · Day-1 short: scale-ladder sort / locus match / gene-vs-allele sort 📝 DRAFT.Meiosis due 4/5 | G38: 4/7 Day-2 long: pipe-cleaner chromosome build · gene map · class allele survey Notes.Genes and Chromosomes due 4/7 | H38: 4/9 IN-SERVICE 4/9 | I38: Digestive System ↗ — Activities — • Fiddle (slides): digestion-path interactive (BioDigital) • Short: Scurvy! case — nutrient function • Long: Villi Absorption sim + Model the Alimentary Canal with String • Alts: Celiac Disease case / Dirty Realities (microbiome) article / enzyme–substrate match | J38: 4/6 Tue: Lesson: Digestive System · Case: Scurvy! | K38: 4/8 Thu: Sim: Villi Absorption + Model the Alimentary Canal with String + Case Study: Celiac Disease · Article: Dirty Realities 🦄 (microbiome) (moved from Fri 4/9 — in-service) | L38: 4/9 OFF — In-Service | M38: Livor, Rigor and Algor Mortis (Time of Death) VT Folder | N38: 4/5 Time of Death: Livor / Rigor / Algor — lesson + short 📝 DRAFT.Stages of Decomposition & The Body Farm due 4/5 | O38: 4/7 Algor Mortis cooling lab · 📝 Notes due | P38: 4/9 OFF — In-Service
A39: Wk 31 | B39: MP 4 | C39: Apr 12 – Apr 16, 2027 | E39: =HYPERLINK("https://drive.google.com/drive/folders/1RKFet7ov0Pfu6kbG1mDfnQKWzGpFHJXA","◆ Cycle 15 · Protein Synthesis Protein Synthesis: Transcription and Translation (Protein Synthesis Extension · Protein Synthesis VT) VT Folder") -> ◆ Cycle 15 · Protein Synthesis Protein Synthesis: Transcription and Translation (Protein Synthesis Extension · Protein Synthesis VT) VT Folder | F39: 4/12 Protein Synthesis lesson · transcription quick-decode DNA→mRNA (short) 📝 DRAFT.Genes and Chromosomes due 4/12 | G39: 4/14 Translation station — build a protein from mRNA with a codon chart (long) Notes.Protein Synthesis due 4/14 | H39: 4/16 Finish labs/activities | I39: Digestive System (cont.) ↗ — Activities — • Fiddle (slides): peristalsis / sphincter animation • Short: Esophagus Length & Cardiac Sphincter Valve lab • Long: digestive-disorders investigation • Alts: Broken Genes case / Label + Concept Map + Coloring (open-book ref) / open-book review before Unit Exam | J39: 4/13 Tue: Lab: Esophagus Length & Cardiac Sphincter Valve | K39: 4/15 Thu: Human Errors: Broken Genes 🦄 · digestive disorders | L39: 4/16 Fri: Open-book review · 📝 UNIT EXAM — Digestive · ref: Label, Concept Map, Coloring | M39: Week 30 Autopsy week VT Folder | N39: 4/12 The Autopsy: Cause vs Manner — lesson + short (Barlow) 📝 DRAFT.Time of Death: Livor / Rigor / Algor Mortis due 4/12 | O39: 4/14 Cause / manner case sort · 📝 Notes due | P39: 4/16 Catch-up / flex (EOW)
A40: Wk 32 | B40: MP 4 | C40: Apr 19 – Apr 23, 2027 | E40: =HYPERLINK("https://drive.google.com/drive/folders/1QUooI_qUo2iLDJCr5gaBdQBc0QHPzxgx","◆ Cycle 16 · Mutations & Gene Expression Cell Differentiation and Gene Expression (Biotechnology · Genetic Mutations · Mutations and Genetic Disorders) VT Folder") -> ◆ Cycle 16 · Mutations & Gene Expression Cell Differentiation and Gene Expression (Biotechnology · Genetic Mutations · Mutations and Genetic Disorders) VT Folder | F40: 4/19 — Activities — Fiddle (on slides): LearnGenetics Build-a-DNA / BioMan gene game. Short: Frameshift 'decode the sequence' — insert/delete a base, re-read the codons. Long: Gel electrophoresis virtual lab (LearnGenetics), or the 'Case of the Desert Bones' DNA-fingerprinting case. Alt: HHMI mutation→phenotype; karyotype / nondisjunction sort for disorders. 📝 DRAFT.Protein Synthesis due 4/19 | G40: 4/21 Notes.Cell Differentiation & Gene Expression due 4/21 | H40: 4/23 Finish labs/activities | I40: Respiratory System ↗ — Activities — • Fiddle (slides): breathing-mechanics animation • Short: Cystic Fibrosis case — structure→function • Long: Spirometry investigation (lung volumes / FEV1) • Alts: Tibetans & High Altitude (adaptation) / bell-jar lung model / gas-exchange diagram | J40: 4/20 Tue: Lesson: Respiratory System · Case: Cystic Fibrosis | K40: 4/22 Thu: Investigation: Spirometry 🦄 (lung volumes / FEV1) | L40: 4/23 Fri: Case Study: Tibetans & High Altitude 🦄 (adaptation) | M40: Autopsy: Fetal Pig Dissection (lab) Folder | N40: 4/19 Fetal Pig Dissection (autopsy lab) 📝 DRAFT.The Autopsy: Cause vs. Manner due 4/19 | O40: 4/21 Pig dissection cont. + pig “funeral” | P40: 4/23 Catch-up / flex (EOW)
...

Sheet Year Task Grid
A1: Prep & Operations Grid — 2026–27 (recurring weekly rhythm; Thu/Fri point at the NEXT week)
A3: Wk / MP | B3: Dates / Off-days | C3: Mon · 1 pd WilmU + grading | D3: Tue · 2 pd Deep work | E3: Wed · 1 pd Deep work | F3: Thu · 2 pd Review next wk + grading scans | G3: Fri Set up next wk labs + groceries
A4: Wk 00 Pre | B4: Pre-service (late Aug 2026) | C4: Set up classroom / WilmU prep | D4: Deep work / year setup | E4: Deep work / year setup | F4: Review Wk 01: Introduction to Biology / Course Overview & First Day / Forensics: First Day & Classroom Rules / Procedures → see Review Links tab | G4: ① Set up Wk 01 labs (light) ② First grocery list → Lab Materials tab
A5: Wk 01 MP1 | B5: Aug 31 – Sep 04, 2026 ⚠ Fri Schools Closed 9/4 | C5: WilmU attendance + grading | D5: Deep work (your choice) | E5: Deep work (your choice) | F5: Review Wk 02: Ecosystems & Change / Introduction to Anatomy / Forensics: Lab Safety, Equipment & the Microscope → see Review Links tab | G5: OFF — Schools Closed 9/4
A6: Wk 02 MP1 | B6: Sep 07 – Sep 11, 2026 ⚠ Mon Labor Day 9/7 | C6: OFF — Labor Day 9/7 | D6: Deep work (your choice) | E6: Deep work (your choice) | F6: Review Wk 03: Intro to Energy / Intro to Anatomy (cont.) / Forensics: Observation Skills & Deductive Reasoning → see Review Links tab | G6: ① Set up labs for Wk 03 ② Grocery / materials list → Lab Materials tab
A7: Wk 03 MP1 | B7: Sep 14 – Sep 18, 2026 ⚠ Tue In-Service 9/15 | C7: WilmU attendance + grading | D7: OFF — In-Service 9/15 | E7: Deep work (your choice) | F7: Review Wk 04: Energy Flow / Cell Structure & Function / Forensics: Eyewitness Testimony & The Innocence Project → see Review Links tab | G7: ① Set up labs for Wk 04 ② Grocery / materials list → Lab Materials tab
A8: Wk 04 MP1 | B8: Sep 21 – Sep 25, 2026 ⚠ Mon Schools Closed 9/21 | C8: OFF — Schools Closed 9/21 | D8: Deep work (your choice) | E8: Deep work (your choice) | F8: Review Wk 05: Biogeochemical Cycles / Cell Structure (cont.) / Forensics: Investigative Processes & Types of Evidence → see Review Links tab | G8: ① Set up labs for Wk 05 ② Grocery / materials list → Lab Materials tab
A9: Wk 05 MP1 | B9: Sep 28 – Oct 02, 2026 | C9: WilmU attendance + grading | D9: Deep work (your choice) | E9: Deep work (your choice) | F9: Review Wk 06: Photosynthesis / Body Tissues / Forensics: Searching & Photographing the Scene → see Review Links tab | G9: ① Set up labs for Wk 06 ② Grocery / materials list → Lab Materials tab
A10: Wk 06 MP1 | B10: Oct 05 – Oct 09, 2026 | C10: WilmU attendance + grading | D10: Deep work (your choice) | E10: Deep work (your choice) | F10: Review Wk 07: Cellular Respiration / Body Tissues (cont.) / Forensics: Sketching the Scene & Evidence Collection → see Review Links tab | G10: ① Set up labs for Wk 07 ② Grocery / materials list → Lab Materials tab
A11: Wk 07 MP1 | B11: Oct 12 – Oct 16, 2026 ⚠ Fri In-Service 10/16 | C11: WilmU attendance + grading | D11: Deep work (your choice) | E11: Deep work (your choice) | F11: Review Wk 08: Fermentation / Skeletal System / Forensics: History of Forensics → see Review Links tab | G11: OFF — In-Service 10/16
A12: Wk 08 MP1 | B12: Oct 19 – Oct 23, 2026 | C12: WilmU attendance + grading | D12: Deep work (your choice) | E12: Deep work (your choice) | F12: Review Wk 09: Ecological Succession / Skeletal System (cont.) / Forensics: Unit Review & Assessment → see Review Links tab | G12: ① Set up labs for Wk 09 ② Grocery / materials list → Lab Materials tab
A13: Wk 09 MP1 | B13: Oct 26 – Oct 30, 2026 | C13: WilmU attendance + grading | D13: Deep work (your choice) | E13: Deep work (your choice) | F13: Review Wk 10: Population Ecology / Skeletal Lab Practical / Forensics: Mock Crime Scene → see Review Links tab | G13: ① Set up labs for Wk 10 ② Grocery / materials list → Lab Materials tab
A14: Wk 10 MP2 | B14: Nov 02 – Nov 06, 2026 ⚠ Tue Election Day 11/3 | C14: WilmU attendance + grading | D14: OFF — Election Day 11/3 | E14: Deep work (your choice) | F14: Review Wk 11: Intro to Cells / Muscular System / Forensics: Arson → see Review Links tab | G14: ① Set up labs for Wk 11 ② Grocery / materials list → Lab Materials tab
... A43: Wk 38 MP4 | B43: May 31 – Jun 04, 2027 (buffer) | C43: WilmU attendance + grading | D43: Deep work (your choice) | E43: Deep work (your choice) | F43: ① Review (year end) → see Review Links tab ② Grading scans: new Notes + finished Drafts | G43: ① Set up labs for year end ② Grocery / materials list → Lab Materials tab

Sheet Labs by date
A1: Lab Materials by Date — set up on the PRIOR Friday · ⚠ materials inferred from lab names — confirm before ordering
A3: Teach week | B3: Lab day(s) | C3: Prep on (prior Fri) | D3: Course | E3: Lab / activity | F3: Buy — groceries / consumables | G3: Reusable equipment | H3: Confirm?
A4: Wk 03 | B4: Mon/Tue | C4: Fri Sep 11 | D4: Bio | E4: Autotroph vs heterotroph card sort | F4: Cardstock (print sets) | G4: — | H4: ✔ DIY print — no order item
A5: Wk 03 | B5: Tue | C5: Fri Sep 11 | D5: A&P | E5: Gummy Bear Dissection (osmosis) | F5: Gummy bears, table salt | G5: Cups, balances | H5: ✔ on order — gummy bears+salt, cups (Grocery line)
A6: Wk 04 | B6: Thu | C6: Fri Sep 18 | D6: A&P | E6: Viewing Human Cells | F6: Methylene blue, toothpicks (cheek cells) | G6: Microscopes, slides, coverslips | H6: ⚠ ADD methylene blue (not on order); toothpicks ✔
A7: Wk 06 | B7: Wed/Thu | C7: Fri Oct 02 | D7: Bio | E7: Leaf Disc Photosynthesis Lab | F7: Baby spinach, baking soda, dish soap | G7: Syringes (no needle), hole punch, clear cups, lamp | H7: ⚠ ADD syringes (not on order); 🛒 spinach+baking soda; dish soap+cups ✔
A8: Wk 06 | B8: Thu | C8: Fri Oct 02 | D8: A&P | E8: Viewing Skin Cells | F8: — | G8: Prepared skin slides, microscopes | H8: ✔ on order — prepared histology slides
